Workbook

Sheet Overview
A1: Floor test matrix: bare against enclosed
A2: Share of planned trials done for each floor, condition, day and radius. Fill in the yellow Done column on the Trials sheet; this grid updates itself.
A4: Drops per radius per block | C4: 5 | D4: 5 per the procedure (section 1); 3 when short on time.
A6: Floor | B6: Condition | C6: Day 1 | G6: Day 2 | K6: All
C7: 1 m | D7: 2 m | E7: 3 m | F7: Noise baselines | G7: 1 m | H7: 2 m | I7: 3 m | J7: Noise baselines
A8: tile | B8: Bare | C8: =IFERROR(SUMIFS(Trials!$L$2:$L$97,Trials!$A$2:$A$97,"tile",Trials!$B$2:$B$97,"Day 1",Trials!$D$2:$D$97,$B8,Trials!$F$2:$F$97,"1 m")/SUMIFS(Trials!$G$2:$G$97,Trials!$A$2:$A$97,"tile",Trials!$B$2:$B$97,"Day 1",Trials!$D$2:$D$97,$B8,Trials!$F$2:$F$97,"1 m"),0) -> 0 | D8: =IFERROR(SUMIFS(Trials!$L$2:$L$97,Trials!$A$2:$A$97,"tile",Trials!$B$2:$B$97,"Day 1",Trials!$D$2:$D$97,$B8,Trials!$F$2:$F$97,"2 m")/SUMIFS(Trials!$G$2:$G$97,Trials!$A$2:$A$97,"tile",Trials!$B$2:$B$97,"Day 1",Trials!$D$2:$D$97,$B8,Trials!$F$2:$F$97,"2 m"),0) -> 0 | E8: =IFERROR(SUMIFS(Trials!$L$2:$L$97,Trials!$A$2:$A$97,"tile",Trials!$B$2:$B$97,"Day 1",Trials!$D$2:$D$97,$B8,Trials!$F$2:$F$97,"3 m")/SUMIFS(Trials!$G$2:$G$97,Trials!$A$2:$A$97,"tile",Trials!$B$2:$B$97,"Day 1",Trials!$D$2:$D$97,$B8,Trials!$F$2:$F$97,"3 m"),0) -> 0 | F8: =IFERROR(SUMIFS(Trials!$L$2:$L$97,Trials!$A$2:$A$97,"tile",Trials!$B$2:$B$97,"Day 1",Trials!$D$2:$D$97,$B8,Trials!$F$2:$F$97,"Noise baseline")/SUMIFS(Trials!$G$2:$G$97,Trials!$A$2:$A$97,"tile",Trials!$B$2:$B$97,"Day 1",Trials!$D$2:$D$97,$B8,Trials!$F$2:$F$97,"Noise baseline"),0) -> 0 | G8: =IFERROR(SUMIFS(Trials!$L$2:$L$97,Trials!$A$2:$A$97,"tile",Trials!$B$2:$B$97,"Day 2",Trials!$D$2:$D$97,$B8,Trials!$F$2:$F$97,"1 m")/SUMIFS(Trials!$G$2:$G$97,Trials!$A$2:$A$97,"tile",Trials!$B$2:$B$97,"Day 2",Trials!$D$2:$D$97,$B8,Trials!$F$2:$F$97,"1 m"),0) -> 0 | H8: =IFERROR(SUMIFS(Trials!$L$2:$L$97,Trials!$A$2:$A$97,"tile",Trials!$B$2:$B$97,"Day 2",Trials!$D$2:$D$97,$B8,Trials!$F$2:$F$97,"2 m")/SUMIFS(Trials!$G$2:$G$97,Trials!$A$2:$A$97,"tile",Trials!$B$2:$B$97,"Day 2",Trials!$D$2:$D$97,$B8,Trials!$F$2:$F$97,"2 m"),0) -> 0 | I8: =IFERROR(SUMIFS(Trials!$L$2:$L$97,Trials!$A$2:$A$97,"tile",Trials!$B$2:$B$97,"Day 2",Trials!$D$2:$D$97,$B8,Trials!$F$2:$F$97,"3 m")/SUMIFS(Trials!$G$2:$G$97,Trials!$A$2:$A$97,"tile",Trials!$B$2:$B$97,"Day 2",Trials!$D$2:$D$97,$B8,Trials!$F$2:$F$97,"3 m"),0) -> 0 | J8: =IFERROR(SUMIFS(Trials!$L$2:$L$97,Trials!$A$2:$A$97,"tile",Trials!$B$2:$B$97,"Day 2",Trials!$D$2:$D$97,$B8,Trials!$F$2:$F$97,"Noise baseline")/SUMIFS(Trials!$G$2:$G$97,Trials!$A$2:$A$97,"tile",Trials!$B$2:$B$97,"Day 2",Trials!$D$2:$D$97,$B8,Trials!$F$2:$F$97,"Noise baseline"),0) -> 0 | K8: =IFERROR(SUMIFS(Trials!$L$2:$L$97,Trials!$A$2:$A$97,"tile",Trials!$D$2:$D$97,$B8)/SUMIFS(Trials!$G$2:$G$97,Trials!$A$2:$A$97,"tile",Trials!$D$2:$D$97,$B8),0) -> 0
B9: Enclosed | C9: =IFERROR(SUMIFS(Trials!$L$2:$L$97,Trials!$A$2:$A$97,"tile",Trials!$B$2:$B$97,"Day 1",Trials!$D$2:$D$97,$B9,Trials!$F$2:$F$97,"1 m")/SUMIFS(Trials!$G$2:$G$97,Trials!$A$2:$A$97,"tile",Trials!$B$2:$B$97,"Day 1",Trials!$D$2:$D$97,$B9,Trials!$F$2:$F$97,"1 m"),0) -> 0 | D9: =IFERROR(SUMIFS(Trials!$L$2:$L$97,Trials!$A$2:$A$97,"tile",Trials!$B$2:$B$97,"Day 1",Trials!$D$2:$D$97,$B9,Trials!$F$2:$F$97,"2 m")/SUMIFS(Trials!$G$2:$G$97,Trials!$A$2:$A$97,"tile",Trials!$B$2:$B$97,"Day 1",Trials!$D$2:$D$97,$B9,Trials!$F$2:$F$97,"2 m"),0) -> 0 | E9: =IFERROR(SUMIFS(Trials!$L$2:$L$97,Trials!$A$2:$A$97,"tile",Trials!$B$2:$B$97,"Day 1",Trials!$D$2:$D$97,$B9,Trials!$F$2:$F$97,"3 m")/SUMIFS(Trials!$G$2:$G$97,Trials!$A$2:$A$97,"tile",Trials!$B$2:$B$97,"Day 1",Trials!$D$2:$D$97,$B9,Trials!$F$2:$F$97,"3 m"),0) -> 0 | F9: =IFERROR(SUMIFS(Trials!$L$2:$L$97,Trials!$A$2:$A$97,"tile",Trials!$B$2:$B$97,"Day 1",Trials!$D$2:$D$97,$B9,Trials!$F$2:$F$97,"Noise baseline")/SUMIFS(Trials!$G$2:$G$97,Trials!$A$2:$A$97,"tile",Trials!$B$2:$B$97,"Day 1",Trials!$D$2:$D$97,$B9,Trials!$F$2:$F$97,"Noise baseline"),0) -> 0 | G9: =IFERROR(SUMIFS(Trials!$L$2:$L$97,Trials!$A$2:$A$97,"tile",Trials!$B$2:$B$97,"Day 2",Trials!$D$2:$D$97,$B9,Trials!$F$2:$F$97,"1 m")/SUMIFS(Trials!$G$2:$G$97,Trials!$A$2:$A$97,"tile",Trials!$B$2:$B$97,"Day 2",Trials!$D$2:$D$97,$B9,Trials!$F$2:$F$97,"1 m"),0) -> 0 | H9: =IFERROR(SUMIFS(Trials!$L$2:$L$97,Trials!$A$2:$A$97,"tile",Trials!$B$2:$B$97,"Day 2",Trials!$D$2:$D$97,$B9,Trials!$F$2:$F$97,"2 m")/SUMIFS(Trials!$G$2:$G$97,Trials!$A$2:$A$97,"tile",Trials!$B$2:$B$97,"Day 2",Trials!$D$2:$D$97,$B9,Trials!$F$2:$F$97,"2 m"),0) -> 0 | I9: =IFERROR(SUMIFS(Trials!$L$2:$L$97,Trials!$A$2:$A$97,"tile",Trials!$B$2:$B$97,"Day 2",Trials!$D$2:$D$97,$B9,Trials!$F$2:$F$97,"3 m")/SUMIFS(Trials!$G$2:$G$97,Trials!$A$2:$A$97,"tile",Trials!$B$2:$B$97,"Day 2",Trials!$D$2:$D$97,$B9,Trials!$F$2:$F$97,"3 m"),0) -> 0 | J9: =IFERROR(SUMIFS(Trials!$L$2:$L$97,Trials!$A$2:$A$97,"tile",Trials!$B$2:$B$97,"Day 2",Trials!$D$2:$D$97,$B9,Trials!$F$2:$F$97,"Noise baseline")/SUMIFS(Trials!$G$2:$G$97,Trials!$A$2:$A$97,"tile",Trials!$B$2:$B$97,"Day 2",Trials!$D$2:$D$97,$B9,Trials!$F$2:$F$97,"Noise baseline"),0) -> 0 | K9: =IFERROR(SUMIFS(Trials!$L$2:$L$97,Trials!$A$2:$A$97,"tile",Trials!$D$2:$D$97,$B9)/SUMIFS(Trials!$G$2:$G$97,Trials!$A$2:$A$97,"tile",Trials!$D$2:$D$97,$B9),0) -> 0
A10: wood | B10: Bare | C10: =IFERROR(SUMIFS(Trials!$L$2:$L$97,Trials!$A$2:$A$97,"wood",Trials!$B$2:$B$97,"Day 1",Trials!$D$2:$D$97,$B10,Trials!$F$2:$F$97,"1 m")/SUMIFS(Trials!$G$2:$G$97,Trials!$A$2:$A$97,"wood",Trials!$B$2:$B$97,"Day 1",Trials!$D$2:$D$97,$B10,Trials!$F$2:$F$97,"1 m"),0) -> 0 | D10: =IFERROR(SUMIFS(Trials!$L$2:$L$97,Trials!$A$2:$A$97,"wood",Trials!$B$2:$B$97,"Day 1",Trials!$D$2:$D$97,$B10,Trials!$F$2:$F$97,"2 m")/SUMIFS(Trials!$G$2:$G$97,Trials!$A$2:$A$97,"wood",Trials!$B$2:$B$97,"Day 1",Trials!$D$2:$D$97,$B10,Trials!$F$2:$F$97,"2 m"),0) -> 0 | E10: =IFERROR(SUMIFS(Trials!$L$2:$L$97,Trials!$A$2:$A$97,"wood",Trials!$B$2:$B$97,"Day 1",Trials!$D$2:$D$97,$B10,Trials!$F$2:$F$97,"3 m")/SUMIFS(Trials!$G$2:$G$97,Trials!$A$2:$A$97,"wood",Trials!$B$2:$B$97,"Day 1",Trials!$D$2:$D$97,$B10,Trials!$F$2:$F$97,"3 m"),0) -> 0 | F10: =IFERROR(SUMIFS(Trials!$L$2:$L$97,Trials!$A$2:$A$97,"wood",Trials!$B$2:$B$97,"Day 1",Trials!$D$2:$D$97,$B10,Trials!$F$2:$F$97,"Noise baseline")/SUMIFS(Trials!$G$2:$G$97,Trials!$A$2:$A$97,"wood",Trials!$B$2:$B$97,"Day 1",Trials!$D$2:$D$97,$B10,Trials!$F$2:$F$97,"Noise baseline"),0) -> 0 | G10: =IFERROR(SUMIFS(Trials!$L$2:$L$97,Trials!$A$2:$A$97,"wood",Trials!$B$2:$B$97,"Day 2",Trials!$D$2:$D$97,$B10,Trials!$F$2:$F$97,"1 m")/SUMIFS(Trials!$G$2:$G$97,Trials!$A$2:$A$97,"wood",Trials!$B$2:$B$97,"Day 2",Trials!$D$2:$D$97,$B10,Trials!$F$2:$F$97,"1 m"),0) -> 0 | H10: =IFERROR(SUMIFS(Trials!$L$2:$L$97,Trials!$A$2:$A$97,"wood",Trials!$B$2:$B$97,"Day 2",Trials!$D$2:$D$97,$B10,Trials!$F$2:$F$97,"2 m")/SUMIFS(Trials!$G$2:$G$97,Trials!$A$2:$A$97,"wood",Trials!$B$2:$B$97,"Day 2",Trials!$D$2:$D$97,$B10,Trials!$F$2:$F$97,"2 m"),0) -> 0 | I10: =IFERROR(SUMIFS(Trials!$L$2:$L$97,Trials!$A$2:$A$97,"wood",Trials!$B$2:$B$97,"Day 2",Trials!$D$2:$D$97,$B10,Trials!$F$2:$F$97,"3 m")/SUMIFS(Trials!$G$2:$G$97,Trials!$A$2:$A$97,"wood",Trials!$B$2:$B$97,"Day 2",Trials!$D$2:$D$97,$B10,Trials!$F$2:$F$97,"3 m"),0) -> 0 | J10: =IFERROR(SUMIFS(Trials!$L$2:$L$97,Trials!$A$2:$A$97,"wood",Trials!$B$2:$B$97,"Day 2",Trials!$D$2:$D$97,$B10,Trials!$F$2:$F$97,"Noise baseline")/SUMIFS(Trials!$G$2:$G$97,Trials!$A$2:$A$97,"wood",Trials!$B$2:$B$97,"Day 2",Trials!$D$2:$D$97,$B10,Trials!$F$2:$F$97,"Noise baseline"),0) -> 0 | K10: =IFERROR(SUMIFS(Trials!$L$2:$L$97,Trials!$A$2:$A$97,"wood",Trials!$D$2:$D$97,$B10)/SUMIFS(Trials!$G$2:$G$97,Trials!$A$2:$A$97,"wood",Trials!$D$2:$D$97,$B10),0) -> 0
B11: Enclosed | C11: =IFERROR(SUMIFS(Trials!$L$2:$L$97,Trials!$A$2:$A$97,"wood",Trials!$B$2:$B$97,"Day 1",Trials!$D$2:$D$97,$B11,Trials!$F$2:$F$97,"1 m")/SUMIFS(Trials!$G$2:$G$97,Trials!$A$2:$A$97,"wood",Trials!$B$2:$B$97,"Day 1",Trials!$D$2:$D$97,$B11,Trials!$F$2:$F$97,"1 m"),0) -> 0 | D11: =IFERROR(SUMIFS(Trials!$L$2:$L$97,Trials!$A$2:$A$97,"wood",Trials!$B$2:$B$97,"Day 1",Trials!$D$2:$D$97,$B11,Trials!$F$2:$F$97,"2 m")/SUMIFS(Trials!$G$2:$G$97,Trials!$A$2:$A$97,"wood",Trials!$B$2:$B$97,"Day 1",Trials!$D$2:$D$97,$B11,Trials!$F$2:$F$97,"2 m"),0) -> 0 | E11: =IFERROR(SUMIFS(Trials!$L$2:$L$97,Trials!$A$2:$A$97,"wood",Trials!$B$2:$B$97,"Day 1",Trials!$D$2:$D$97,$B11,Trials!$F$2:$F$97,"3 m")/SUMIFS(Trials!$G$2:$G$97,Trials!$A$2:$A$97,"wood",Trials!$B$2:$B$97,"Day 1",Trials!$D$2:$D$97,$B11,Trials!$F$2:$F$97,"3 m"),0) -> 0 | F11: =IFERROR(SUMIFS(Trials!$L$2:$L$97,Trials!$A$2:$A$97,"wood",Trials!$B$2:$B$97,"Day 1",Trials!$D$2:$D$97,$B11,Trials!$F$2:$F$97,"Noise baseline")/SUMIFS(Trials!$G$2:$G$97,Trials!$A$2:$A$97,"wood",Trials!$B$2:$B$97,"Day 1",Trials!$D$2:$D$97,$B11,Trials!$F$2:$F$97,"Noise baseline"),0) -> 0 | G11: =IFERROR(SUMIFS(Trials!$L$2:$L$97,Trials!$A$2:$A$97,"wood",Trials!$B$2:$B$97,"Day 2",Trials!$D$2:$D$97,$B11,Trials!$F$2:$F$97,"1 m")/SUMIFS(Trials!$G$2:$G$97,Trials!$A$2:$A$97,"wood",Trials!$B$2:$B$97,"Day 2",Trials!$D$2:$D$97,$B11,Trials!$F$2:$F$97,"1 m"),0) -> 0 | H11: =IFERROR(SUMIFS(Trials!$L$2:$L$97,Trials!$A$2:$A$97,"wood",Trials!$B$2:$B$97,"Day 2",Trials!$D$2:$D$97,$B11,Trials!$F$2:$F$97,"2 m")/SUMIFS(Trials!$G$2:$G$97,Trials!$A$2:$A$97,"wood",Trials!$B$2:$B$97,"Day 2",Trials!$D$2:$D$97,$B11,Trials!$F$2:$F$97,"2 m"),0) -> 0 | I11: =IFERROR(SUMIFS(Trials!$L$2:$L$97,Trials!$A$2:$A$97,"wood",Trials!$B$2:$B$97,"Day 2",Trials!$D$2:$D$97,$B11,Trials!$F$2:$F$97,"3 m")/SUMIFS(Trials!$G$2:$G$97,Trials!$A$2:$A$97,"wood",Trials!$B$2:$B$97,"Day 2",Trials!$D$2:$D$97,$B11,Trials!$F$2:$F$97,"3 m"),0) -> 0 | J11: =IFERROR(SUMIFS(Trials!$L$2:$L$97,Trials!$A$2:$A$97,"wood",Trials!$B$2:$B$97,"Day 2",Trials!$D$2:$D$97,$B11,Trials!$F$2:$F$97,"Noise baseline")/SUMIFS(Trials!$G$2:$G$97,Trials!$A$2:$A$97,"wood",Trials!$B$2:$B$97,"Day 2",Trials!$D$2:$D$97,$B11,Trials!$F$2:$F$97,"Noise baseline"),0) -> 0 | K11: =IFERROR(SUMIFS(Trials!$L$2:$L$97,Trials!$A$2:$A$97,"wood",Trials!$D$2:$D$97,$B11)/SUMIFS(Trials!$G$2:$G$97,Trials!$A$2:$A$97,"wood",Trials!$D$2:$D$97,$B11),0) -> 0
A12: carpet | B12: Bare | C12: =IFERROR(SUMIFS(Trials!$L$2:$L$97,Trials!$A$2:$A$97,"carpet",Trials!$B$2:$B$97,"Day 1",Trials!$D$2:$D$97,$B12,Trials!$F$2:$F$97,"1 m")/SUMIFS(Trials!$G$2:$G$97,Trials!$A$2:$A$97,"carpet",Trials!$B$2:$B$97,"Day 1",Trials!$D$2:$D$97,$B12,Trials!$F$2:$F$97,"1 m"),0) -> 0 | D12: =IFERROR(SUMIFS(Trials!$L$2:$L$97,Trials!$A$2:$A$97,"carpet",Trials!$B$2:$B$97,"Day 1",Trials!$D$2:$D$97,$B12,Trials!$F$2:$F$97,"2 m")/SUMIFS(Trials!$G$2:$G$97,Trials!$A$2:$A$97,"carpet",Trials!$B$2:$B$97,"Day 1",Trials!$D$2:$D$97,$B12,Trials!$F$2:$F$97,"2 m"),0) -> 0 | E12: =IFERROR(SUMIFS(Trials!$L$2:$L$97,Trials!$A$2:$A$97,"carpet",Trials!$B$2:$B$97,"Day 1",Trials!$D$2:$D$97,$B12,Trials!$F$2:$F$97,"3 m")/SUMIFS(Trials!$G$2:$G$97,Trials!$A$2:$A$97,"carpet",Trials!$B$2:$B$97,"Day 1",Trials!$D$2:$D$97,$B12,Trials!$F$2:$F$97,"3 m"),0) -> 0 | F12: =IFERROR(SUMIFS(Trials!$L$2:$L$97,Trials!$A$2:$A$97,"carpet",Trials!$B$2:$B$97,"Day 1",Trials!$D$2:$D$97,$B12,Trials!$F$2:$F$97,"Noise baseline")/SUMIFS(Trials!$G$2:$G$97,Trials!$A$2:$A$97,"carpet",Trials!$B$2:$B$97,"Day 1",Trials!$D$2:$D$97,$B12,Trials!$F$2:$F$97,"Noise baseline"),0) -> 0 | G12: =IFERROR(SUMIFS(Trials!$L$2:$L$97,Trials!$A$2:$A$97,"carpet",Trials!$B$2:$B$97,"Day 2",Trials!$D$2:$D$97,$B12,Trials!$F$2:$F$97,"1 m")/SUMIFS(Trials!$G$2:$G$97,Trials!$A$2:$A$97,"carpet",Trials!$B$2:$B$97,"Day 2",Trials!$D$2:$D$97,$B12,Trials!$F$2:$F$97,"1 m"),0) -> 0 | H12: =IFERROR(SUMIFS(Trials!$L$2:$L$97,Trials!$A$2:$A$97,"carpet",Trials!$B$2:$B$97,"Day 2",Trials!$D$2:$D$97,$B12,Trials!$F$2:$F$97,"2 m")/SUMIFS(Trials!$G$2:$G$97,Trials!$A$2:$A$97,"carpet",Trials!$B$2:$B$97,"Day 2",Trials!$D$2:$D$97,$B12,Trials!$F$2:$F$97,"2 m"),0) -> 0 | I12: =IFERROR(SUMIFS(Trials!$L$2:$L$97,Trials!$A$2:$A$97,"carpet",Trials!$B$2:$B$97,"Day 2",Trials!$D$2:$D$97,$B12,Trials!$F$2:$F$97,"3 m")/SUMIFS(Trials!$G$2:$G$97,Trials!$A$2:$A$97,"carpet",Trials!$B$2:$B$97,"Day 2",Trials!$D$2:$D$97,$B12,Trials!$F$2:$F$97,"3 m"),0) -> 0 | J12: =IFERROR(SUMIFS(Trials!$L$2:$L$97,Trials!$A$2:$A$97,"carpet",Trials!$B$2:$B$97,"Day 2",Trials!$D$2:$D$97,$B12,Trials!$F$2:$F$97,"Noise baseline")/SUMIFS(Trials!$G$2:$G$97,Trials!$A$2:$A$97,"carpet",Trials!$B$2:$B$97,"Day 2",Trials!$D$2:$D$97,$B12,Trials!$F$2:$F$97,"Noise baseline"),0) -> 0 | K12: =IFERROR(SUMIFS(Trials!$L$2:$L$97,Trials!$A$2:$A$97,"carpet",Trials!$D$2:$D$97,$B12)/SUMIFS(Trials!$G$2:$G$97,Trials!$A$2:$A$97,"carpet",Trials!$D$2:$D$97,$B12),0) -> 0
B13: Enclosed | C13: =IFERROR(SUMIFS(Trials!$L$2:$L$97,Trials!$A$2:$A$97,"carpet",Trials!$B$2:$B$97,"Day 1",Trials!$D$2:$D$97,$B13,Trials!$F$2:$F$97,"1 m")/SUMIFS(Trials!$G$2:$G$97,Trials!$A$2:$A$97,"carpet",Trials!$B$2:$B$97,"Day 1",Trials!$D$2:$D$97,$B13,Trials!$F$2:$F$97,"1 m"),0) -> 0 | D13: =IFERROR(SUMIFS(Trials!$L$2:$L$97,Trials!$A$2:$A$97,"carpet",Trials!$B$2:$B$97,"Day 1",Trials!$D$2:$D$97,$B13,Trials!$F$2:$F$97,"2 m")/SUMIFS(Trials!$G$2:$G$97,Trials!$A$2:$A$97,"carpet",Trials!$B$2:$B$97,"Day 1",Trials!$D$2:$D$97,$B13,Trials!$F$2:$F$97,"2 m"),0) -> 0 | E13: =IFERROR(SUMIFS(Trials!$L$2:$L$97,Trials!$A$2:$A$97,"carpet",Trials!$B$2:$B$97,"Day 1",Trials!$D$2:$D$97,$B13,Trials!$F$2:$F$97,"3 m")/SUMIFS(Trials!$G$2:$G$97,Trials!$A$2:$A$97,"carpet",Trials!$B$2:$B$97,"Day 1",Trials!$D$2:$D$97,$B13,Trials!$F$2:$F$97,"3 m"),0) -> 0 | F13: =IFERROR(SUMIFS(Trials!$L$2:$L$97,Trials!$A$2:$A$97,"carpet",Trials!$B$2:$B$97,"Day 1",Trials!$D$2:$D$97,$B13,Trials!$F$2:$F$97,"Noise baseline")/SUMIFS(Trials!$G$2:$G$97,Trials!$A$2:$A$97,"carpet",Trials!$B$2:$B$97,"Day 1",Trials!$D$2:$D$97,$B13,Trials!$F$2:$F$97,"Noise baseline"),0) -> 0 | G13: =IFERROR(SUMIFS(Trials!$L$2:$L$97,Trials!$A$2:$A$97,"carpet",Trials!$B$2:$B$97,"Day 2",Trials!$D$2:$D$97,$B13,Trials!$F$2:$F$97,"1 m")/SUMIFS(Trials!$G$2:$G$97,Trials!$A$2:$A$97,"carpet",Trials!$B$2:$B$97,"Day 2",Trials!$D$2:$D$97,$B13,Trials!$F$2:$F$97,"1 m"),0) -> 0 | H13: =IFERROR(SUMIFS(Trials!$L$2:$L$97,Trials!$A$2:$A$97,"carpet",Trials!$B$2:$B$97,"Day 2",Trials!$D$2:$D$97,$B13,Trials!$F$2:$F$97,"2 m")/SUMIFS(Trials!$G$2:$G$97,Trials!$A$2:$A$97,"carpet",Trials!$B$2:$B$97,"Day 2",Trials!$D$2:$D$97,$B13,Trials!$F$2:$F$97,"2 m"),0) -> 0 | I13: =IFERROR(SUMIFS(Trials!$L$2:$L$97,Trials!$A$2:$A$97,"carpet",Trials!$B$2:$B$97,"Day 2",Trials!$D$2:$D$97,$B13,Trials!$F$2:$F$97,"3 m")/SUMIFS(Trials!$G$2:$G$97,Trials!$A$2:$A$97,"carpet",Trials!$B$2:$B$97,"Day 2",Trials!$D$2:$D$97,$B13,Trials!$F$2:$F$97,"3 m"),0) -> 0 | J13: =IFERROR(SUMIFS(Trials!$L$2:$L$97,Trials!$A$2:$A$97,"carpet",Trials!$B$2:$B$97,"Day 2",Trials!$D$2:$D$97,$B13,Trials!$F$2:$F$97,"Noise baseline")/SUMIFS(Trials!$G$2:$G$97,Trials!$A$2:$A$97,"carpet",Trials!$B$2:$B$97,"Day 2",Trials!$D$2:$D$97,$B13,Trials!$F$2:$F$97,"Noise baseline"),0) -> 0 | K13: =IFERROR(SUMIFS(Trials!$L$2:$L$97,Trials!$A$2:$A$97,"carpet",Trials!$D$2:$D$97,$B13)/SUMIFS(Trials!$G$2:$G$97,Trials!$A$2:$A$97,"carpet",Trials!$D$2:$D$97,$B13),0) -> 0
A14: All floors | C14: =IFERROR(SUMIFS(Trials!$L$2:$L$97,Trials!$B$2:$B$97,"Day 1",Trials!$F$2:$F$97,"1 m")/SUMIFS(Trials!$G$2:$G$97,Trials!$B$2:$B$97,"Day 1",Trials!$F$2:$F$97,"1 m"),0) -> 0 | D14: =IFERROR(SUMIFS(Trials!$L$2:$L$97,Trials!$B$2:$B$97,"Day 1",Trials!$F$2:$F$97,"2 m")/SUMIFS(Trials!$G$2:$G$97,Trials!$B$2:$B$97,"Day 1",Trials!$F$2:$F$97,"2 m"),0) -> 0 | E14: =IFERROR(SUMIFS(Trials!$L$2:$L$97,Trials!$B$2:$B$97,"Day 1",Trials!$F$2:$F$97,"3 m")/SUMIFS(Trials!$G$2:$G$97,Trials!$B$2:$B$97,"Day 1",Trials!$F$2:$F$97,"3 m"),0) -> 0 | F14: =IFERROR(SUMIFS(Trials!$L$2:$L$97,Trials!$B$2:$B$97,"Day 1",Trials!$F$2:$F$97,"Noise baseline")/SUMIFS(Trials!$G$2:$G$97,Trials!$B$2:$B$97,"Day 1",Trials!$F$2:$F$97,"Noise baseline"),0) -> 0 | G14: =IFERROR(SUMIFS(Trials!$L$2:$L$97,Trials!$B$2:$B$97,"Day 2",Trials!$F$2:$F$97,"1 m")/SUMIFS(Trials!$G$2:$G$97,Trials!$B$2:$B$97,"Day 2",Trials!$F$2:$F$97,"1 m"),0) -> 0 | H14: =IFERROR(SUMIFS(Trials!$L$2:$L$97,Trials!$B$2:$B$97,"Day 2",Trials!$F$2:$F$97,"2 m")/SUMIFS(Trials!$G$2:$G$97,Trials!$B$2:$B$97,"Day 2",Trials!$F$2:$F$97,"2 m"),0) -> 0 | I14: =IFERROR(SUMIFS(Trials!$L$2:$L$97,Trials!$B$2:$B$97,"Day 2",Trials!$F$2:$F$97,"3 m")/SUMIFS(Trials!$G$2:$G$97,Trials!$B$2:$B$97,"Day 2",Trials!$F$2:$F$97,"3 m"),0) -> 0 | J14: =IFERROR(SUMIFS(Trials!$L$2:$L$97,Trials!$B$2:$B$97,"Day 2",Trials!$F$2:$F$97,"Noise baseline")/SUMIFS(Trials!$G$2:$G$97,Trials!$B$2:$B$97,"Day 2",Trials!$F$2:$F$97,"Noise baseline"),0) -> 0 | K14: =IFERROR(SUM(Trials!$L$2:$L$97)/SUM(Trials!$G$2:$G$97),0) -> 0
C16: Every planned trial done
C17: Started, not finished
C18: Not started
A20: Each grid cell covers both blocks of that condition (blocks 1 and 3 bare, 2 and 4 enclosed), so 100% at a radius is 2 × the drops per block.
A21: Noise baselines: one 60 s baseline per block, so 2 per condition per day.
A22: Day 2 repeats the same plan on the same floor on a different day and at a different time of day.
A23: The procedure is docs/testing/floor_procedure.md.

Sheet Trials
A1: Floor | B1: Day | C1: Block | D1: Condition | E1: ID prefix | F1: Radius | G1: Planned | H1: Done | I1: Status | J1: Date done | K1: Notes | L1: Counted (auto)
A2: tile | B2: Day 1 | C2: 1 | D2: Bare | E2: tile_bare_1 | F2: Noise baseline | G2: 1 | I2: =IF(H2="","Not started",IF(H2>=G2,"Done","Partial")) -> Not started | L2: =MIN(N(H2),G2) -> 0
A3: tile | B3: Day 1 | C3: 1 | D3: Bare | E3: tile_bare_1 | F3: 1 m | G3: =Overview!$C$4 -> 5 | I3: =IF(H3="","Not started",IF(H3>=G3,"Done","Partial")) -> Not started | L3: =MIN(N(H3),G3) -> 0
A4: tile | B4: Day 1 | C4: 1 | D4: Bare | E4: tile_bare_1 | F4: 2 m | G4: =Overview!$C$4 -> 5 | I4: =IF(H4="","Not started",IF(H4>=G4,"Done","Partial")) -> Not started | L4: =MIN(N(H4),G4) -> 0
A5: tile | B5: Day 1 | C5: 1 | D5: Bare | E5: tile_bare_1 | F5: 3 m | G5: =Overview!$C$4 -> 5 | I5: =IF(H5="","Not started",IF(H5>=G5,"Done","Partial")) -> Not started | L5: =MIN(N(H5),G5) -> 0
A6: tile | B6: Day 1 | C6: 2 | D6: Enclosed | E6: tile_vase_1 | F6: Noise baseline | G6: 1 | I6: =IF(H6="","Not started",IF(H6>=G6,"Done","Partial")) -> Not started | L6: =MIN(N(H6),G6) -> 0
A7: tile | B7: Day 1 | C7: 2 | D7: Enclosed | E7: tile_vase_1 | F7: 1 m | G7: =Overview!$C$4 -> 5 | I7: =IF(H7="","Not started",IF(H7>=G7,"Done","Partial")) -> Not started | L7: =MIN(N(H7),G7) -> 0
A8: tile | B8: Day 1 | C8: 2 | D8: Enclosed | E8: tile_vase_1 | F8: 2 m | G8: =Overview!$C$4 -> 5 | I8: =IF(H8="","Not started",IF(H8>=G8,"Done","Partial")) -> Not started | L8: =MIN(N(H8),G8) -> 0
A9: tile | B9: Day 1 | C9: 2 | D9: Enclosed | E9: tile_vase_1 | F9: 3 m | G9: =Overview!$C$4 -> 5 | I9: =IF(H9="","Not started",IF(H9>=G9,"Done","Partial")) -> Not started | L9: =MIN(N(H9),G9) -> 0
A10: tile | B10: Day 1 | C10: 3 | D10: Bare | E10: tile_bare_2 | F10: Noise baseline | G10: 1 | I10: =IF(H10="","Not started",IF(H10>=G10,"Done","Partial")) -> Not started | L10: =MIN(N(H10),G10) -> 0
A11: tile | B11: Day 1 | C11: 3 | D11: Bare | E11: tile_bare_2 | F11: 1 m | G11: =Overview!$C$4 -> 5 | I11: =IF(H11="","Not started",IF(H11>=G11,"Done","Partial")) -> Not started | L11: =MIN(N(H11),G11) -> 0
A12: tile | B12: Day 1 | C12: 3 | D12: Bare | E12: tile_bare_2 | F12: 2 m | G12: =Overview!$C$4 -> 5 | I12: =IF(H12="","Not started",IF(H12>=G12,"Done","Partial")) -> Not started | L12: =MIN(N(H12),G12) -> 0
A13: tile | B13: Day 1 | C13: 3 | D13: Bare | E13: tile_bare_2 | F13: 3 m | G13: =Overview!$C$4 -> 5 | I13: =IF(H13="","Not started",IF(H13>=G13,"Done","Partial")) -> Not started | L13: =MIN(N(H13),G13) -> 0
A14: tile | B14: Day 1 | C14: 4 | D14: Enclosed | E14: tile_vase_2 | F14: Noise baseline | G14: 1 | I14: =IF(H14="","Not started",IF(H14>=G14,"Done","Partial")) -> Not started | L14: =MIN(N(H14),G14) -> 0
A15: tile | B15: Day 1 | C15: 4 | D15: Enclosed | E15: tile_vase_2 | F15: 1 m | G15: =Overview!$C$4 -> 5 | I15: =IF(H15="","Not started",IF(H15>=G15,"Done","Partial")) -> Not started | L15: =MIN(N(H15),G15) -> 0
A16: tile | B16: Day 1 | C16: 4 | D16: Enclosed | E16: tile_vase_2 | F16: 2 m | G16: =Overview!$C$4 -> 5 | I16: =IF(H16="","Not started",IF(H16>=G16,"Done","Partial")) -> Not started | L16: =MIN(N(H16),G16) -> 0
A17: tile | B17: Day 1 | C17: 4 | D17: Enclosed | E17: tile_vase_2 | F17: 3 m | G17: =Overview!$C$4 -> 5 | I17: =IF(H17="","Not started",IF(H17>=G17,"Done","Partial")) -> Not started | L17: =MIN(N(H17),G17) -> 0
A18: tile | B18: Day 2 | C18: 1 | D18: Bare | E18: tile_bare_1 | F18: Noise baseline | G18: 1 | I18: =IF(H18="","Not started",IF(H18>=G18,"Done","Partial")) -> Not started | L18: =MIN(N(H18),G18) -> 0
A19: tile | B19: Day 2 | C19: 1 | D19: Bare | E19: tile_bare_1 | F19: 1 m | G19: =Overview!$C$4 -> 5 | I19: =IF(H19="","Not started",IF(H19>=G19,"Done","Partial")) -> Not started | L19: =MIN(N(H19),G19) -> 0
A20: tile | B20: Day 2 | C20: 1 | D20: Bare | E20: tile_bare_1 | F20: 2 m | G20: =Overview!$C$4 -> 5 | I20: =IF(H20="","Not started",IF(H20>=G20,"Done","Partial")) -> Not started | L20: =MIN(N(H20),G20) -> 0
A21: tile | B21: Day 2 | C21: 1 | D21: Bare | E21: tile_bare_1 | F21: 3 m | G21: =Overview!$C$4 -> 5 | I21: =IF(H21="","Not started",IF(H21>=G21,"Done","Partial")) -> Not started | L21: =MIN(N(H21),G21) -> 0
A22: tile | B22: Day 2 | C22: 2 | D22: Enclosed | E22: tile_vase_1 | F22: Noise baseline | G22: 1 | I22: =IF(H22="","Not started",IF(H22>=G22,"Done","Partial")) -> Not started | L22: =MIN(N(H22),G22) -> 0
A23: tile | B23: Day 2 | C23: 2 | D23: Enclosed | E23: tile_vase_1 | F23: 1 m | G23: =Overview!$C$4 -> 5 | I23: =IF(H23="","Not started",IF(H23>=G23,"Done","Partial")) -> Not started | L23: =MIN(N(H23),G23) -> 0
A24: tile | B24: Day 2 | C24: 2 | D24: Enclosed | E24: tile_vase_1 | F24: 2 m | G24: =Overview!$C$4 -> 5 | I24: =IF(H24="","Not started",IF(H24>=G24,"Done","Partial")) -> Not started | L24: =MIN(N(H24),G24) -> 0
A25: tile | B25: Day 2 | C25: 2 | D25: Enclosed | E25: tile_vase_1 | F25: 3 m | G25: =Overview!$C$4 -> 5 | I25: =IF(H25="","Not started",IF(H25>=G25,"Done","Partial")) -> Not started | L25: =MIN(N(H25),G25) -> 0
A26: tile | B26: Day 2 | C26: 3 | D26: Bare | E26: tile_bare_2 | F26: Noise baseline | G26: 1 | I26: =IF(H26="","Not started",IF(H26>=G26,"Done","Partial")) -> Not started | L26: =MIN(N(H26),G26) -> 0
A27: tile | B27: Day 2 | C27: 3 | D27: Bare | E27: tile_bare_2 | F27: 1 m | G27: =Overview!$C$4 -> 5 | I27: =IF(H27="","Not started",IF(H27>=G27,"Done","Partial")) -> Not started | L27: =MIN(N(H27),G27) -> 0
A28: tile | B28: Day 2 | C28: 3 | D28: Bare | E28: tile_bare_2 | F28: 2 m | G28: =Overview!$C$4 -> 5 | I28: =IF(H28="","Not started",IF(H28>=G28,"Done","Partial")) -> Not started | L28: =MIN(N(H28),G28) -> 0
A29: tile | B29: Day 2 | C29: 3 | D29: Bare | E29: tile_bare_2 | F29: 3 m | G29: =Overview!$C$4 -> 5 | I29: =IF(H29="","Not started",IF(H29>=G29,"Done","Partial")) -> Not started | L29: =MIN(N(H29),G29) -> 0
A30: tile | B30: Day 2 | C30: 4 | D30: Enclosed | E30: tile_vase_2 | F30: Noise baseline | G30: 1 | I30: =IF(H30="","Not started",IF(H30>=G30,"Done","Partial")) -> Not started | L30: =MIN(N(H30),G30) -> 0
A31: tile | B31: Day 2 | C31: 4 | D31: Enclosed | E31: tile_vase_2 | F31: 1 m | G31: =Overview!$C$4 -> 5 | I31: =IF(H31="","Not started",IF(H31>=G31,"Done","Partial")) -> Not started | L31: =MIN(N(H31),G31) -> 0
A32: tile | B32: Day 2 | C32: 4 | D32: Enclosed | E32: tile_vase_2 | F32: 2 m | G32: =Overview!$C$4 -> 5 | I32: =IF(H32="","Not started",IF(H32>=G32,"Done","Partial")) -> Not started | L32: =MIN(N(H32),G32) -> 0
A33: tile | B33: Day 2 | C33: 4 | D33: Enclosed | E33: tile_vase_2 | F33: 3 m | G33: =Overview!$C$4 -> 5 | I33: =IF(H33="","Not started",IF(H33>=G33,"Done","Partial")) -> Not started | L33: =MIN(N(H33),G33) -> 0
A34: wood | B34: Day 1 | C34: 1 | D34: Bare | E34: wood_bare_1 | F34: Noise baseline | G34: 1 | I34: =IF(H34="","Not started",IF(H34>=G34,"Done","Partial")) -> Not started | L34: =MIN(N(H34),G34) -> 0
A35: wood | B35: Day 1 | C35: 1 | D35: Bare | E35: wood_bare_1 | F35: 1 m | G35: =Overview!$C$4 -> 5 | I35: =IF(H35="","Not started",IF(H35>=G35,"Done","Partial")) -> Not started | L35: =MIN(N(H35),G35) -> 0
A36: wood | B36: Day 1 | C36: 1 | D36: Bare | E36: wood_bare_1 | F36: 2 m | G36: =Overview!$C$4 -> 5 | I36: =IF(H36="","Not started",IF(H36>=G36,"Done","Partial")) -> Not started | L36: =MIN(N(H36),G36) -> 0
A37: wood | B37: Day 1 | C37: 1 | D37: Bare | E37: wood_bare_1 | F37: 3 m | G37: =Overview!$C$4 -> 5 | I37: =IF(H37="","Not started",IF(H37>=G37,"Done","Partial")) -> Not started | L37: =MIN(N(H37),G37) -> 0
A38: wood | B38: Day 1 | C38: 2 | D38: Enclosed | E38: wood_vase_1 | F38: Noise baseline | G38: 1 | I38: =IF(H38="","Not started",IF(H38>=G38,"Done","Partial")) -> Not started | L38: =MIN(N(H38),G38) -> 0
A39: wood | B39: Day 1 | C39: 2 | D39: Enclosed | E39: wood_vase_1 | F39: 1 m | G39: =Overview!$C$4 -> 5 | I39: =IF(H39="","Not started",IF(H39>=G39,"Done","Partial")) -> Not started | L39: =MIN(N(H39),G39) -> 0
A40: wood | B40: Day 1 | C40: 2 | D40: Enclosed | E40: wood_vase_1 | F40: 2 m | G40: =Overview!$C$4 -> 5 | I40: =IF(H40="","Not started",IF(H40>=G40,"Done","Partial")) -> Not started | L40: =MIN(N(H40),G40) -> 0
...

Sheet How to use
A1: How to use this matrix
A3: Edit only the yellow cells.
A4: Trials sheet: Done (number of good trials), Date done, Notes.
A5: Overview sheet: Drops per radius per block (C4), if you run 3 drops instead of 5.
A6: Everything else is a label or a formula.
A8: One row per block and radius. Each block starts with its noise baseline row, then 1, 2 and 3 m.
A9: Shuffle the radius order inside each block when you run it (procedure section 1); the row order here is only for the checklist.
A10: A trial marked invalid and repeated counts once. Write the reason in Notes.
A11: Filter the Trials sheet by Floor, Day or Status to see what is left.
A13: Example of a filled-in row (not counted anywhere):
A14: Floor | B14: Day | C14: Block | D14: Condition | E14: ID prefix | F14: Radius | G14: Planned | H14: Done | I14: Status | J14: Date done | K14: Notes
A15: tile | B15: Day 1 | C15: 2 | D15: Enclosed | E15: tile_vase_1 | F15: 2 m | G15: 5 | H15: 4 | I15: Partial | J15: 2026-10-22 | K15: drop 3 repeated (ball rolled); one left to do
